Workbook

Sheet Summary
A1: Sales Report — Audit Summary
A2: Period: All Time
A3: This is a working sheet. Each marketplace tab has 200 blank rows under the data: type a Buy Price and a Sale Price and the whole row calculates in Excel, and the figures here follow. Leave the calculated columns alone — typing over one replaces live maths with a frozen number. Nothing reads this file back into the application; sales are recorded under Sell.
A5: Marketplace | B5: Sales | C5: Refunds | D5: Replacements | E5: Repairs | F5: Gross GP £ | G5: Return Cost £ | H5: Net GP £ | I5: Net GP %
A6: AMAZON | B6: =21+COUNT('AMAZON'!$H$23:$H$222) | C6: 0 | D6: 0 | E6: 0 | F6: =1112.38+SUM('AMAZON'!$V$23:$V$222) | G6: 0 | H6: =F6-G6 | I6: =IFERROR((F6-G6)/(6415.50+SUM('AMAZON'!$G$23:$G$222))*100,0)
A7: BM | B7: =20+COUNT('BM'!$H$22:$H$221) | C7: 0 | D7: 0 | E7: 0 | F7: =664.49+SUM('BM'!$U$22:$U$221) | G7: 0 | H7: =F7-G7 | I7: =IFERROR((F7-G7)/(6673.31+SUM('BM'!$G$22:$G$221))*100,0)
A8: EBAY | B8: =20+COUNT('EBAY'!$H$22:$H$221) | C8: 0 | D8: 0 | E8: 0 | F8: =1278.25+SUM('EBAY'!$Y$22:$Y$221) | G8: 0 | H8: =F8-G8 | I8: =IFERROR((F8-G8)/(6437.01+SUM('EBAY'!$G$22:$G$221))*100,0)
A9: ONBUY | B9: =20+COUNT('ONBUY'!$G$22:$G$221) | C9: 0 | D9: 0 | E9: 0 | F9: =1133.34+SUM('ONBUY'!$S$22:$S$221) | G9: 0 | H9: =F9-G9 | I9: =IFERROR((F9-G9)/(6683.97+SUM('ONBUY'!$F$22:$F$221))*100,0)
A10: TEMU | B10: =20+COUNT('TEMU'!$H$22:$H$221) | C10: 0 | D10: 0 | E10: 0 | F10: =1336.79+SUM('TEMU'!$U$22:$U$221) | G10: 0 | H10: =F10-G10 | I10: =IFERROR((F10-G10)/(6826.54+SUM('TEMU'!$G$22:$G$221))*100,0)
A11: TOTAL | B11: =B6+B7+B8+B9+B10 | C11: =C6+C7+C8+C9+C10 | D11: =D6+D7+D8+D9+D10 | E11: =E6+E7+E8+E9+E10 | F11: =F6+F7+F8+F9+F10 | G11: =G6+G7+G8+G9+G10 | H11: =H6+H7+H8+H9+H10 | I11: =IFERROR((F11-G11)/(33036.33+SUM('AMAZON'!$G$23:$G$222)+SUM('BM'!$G$22:$G$221)+SUM('EBAY'!$G$22:$G$221)+SUM('ONBUY'!$F$22:$F$221)+SUM('TEMU'!$G$22:$G$221))*100,0)
A13: Notes
A14: • Refunds + Repairs + Return-to-Supplier each eat 2 shipping legs (outbound + inbound). Replacements eat 3 (plus the replacement outbound).
A15: • Repair: the unit comes back to stock, but both carriage legs were still paid — so it carries the same 2-leg loss as a refund.
A16: • Postage Loss = (postage + P.VAT) × legs, snapshotted at Process Return time. eBay legs carry no VAT — its shipping is zero-rated.
A17: • Fees Kept = what the marketplace did not give back on a refund: Amazon min(20% × commission, £5) + VAT; eBay the fixed £0.40 + VAT; Back Market / OnBuy / Temu keep every fee they charged. Blank on replacements — no refund reached the marketplace.
A18: • Return Cost = Postage Loss + Fees Kept + Repair Cost − Supplier Credit (a live formula on each returned row). A blank Repair Cost means the invoice has not been entered yet — the Returns page flags these.
A19: • Net GP = Gross GP − Return Cost. Net GP % = Net GP ÷ BP (× 100). eBay rows divide by SP per platform convention.
A20: • Sales / Gross GP / BP above count ACTIVE sales only — matching the app's ALL-TIME SOLD figure. Refunds, Replacements and Repairs are tracked separately in the columns to the left; add them to Sales for this sheet's row count on each marketplace tab.
A21: • Per-marketplace sheets carry a TOTAL row at the bottom summing every row shown there (active + returned) via SUM formulas — the Returns tab breaks the returned rows out on their own.

Sheet AMAZON
A1: Date | B1: Order Number | C1: SKU | D1: IMEI | E1: Model | F1: Colour | G1: Storage | H1: Supplier | I1: Quantity | J1: BP | K1: SP | L1: SP-BP | M1: Marginal Tax | N1: Commission | O1: C. VAT | P1: DSF | Q1: DSF. VAT | R1: Postage | S1: P. VAT | T1: Acc | U1: Total VAT | V1: GP | W1: GP % | X1: Total VAT NTP | Y1: Postage Loss | Z1: Fees Kept | AA1: Repair Cost | AB1: Supplier Credit | AC1: Return Cost | AD1: Net GP £ | AE1: Return Date | AF1: Outcome | AG1: Shipping Legs | AH1: Return Reason | AI1: Comments
A2: 46227.5 | B2: AMA-SHS-1 | C2: IPH-64GB-GRA | D2: 350190000007777 | E2: iPhone | F2: Unspecified | G2: 64GB | H2: NORTHSIDE STOCK | I2: 1 | J2: 206.45 | K2: 268.39 | L2: =K2-J2 | M2: =L2*16.67% | N2: =K2/100*7 | O2: =N2*20% | P2: =N2*2% | Q2: =P2*20% | R2: 8 | S2: =R2*20% | T2: 1 | U2: =O2+Q2+S2 | V2: =L2-M2-N2-O2-P2-Q2-R2-S2-T2 | W2: =(V2-AC2)/J2*100 | X2: =M2-U2 | AD2: =V2-AC2
A3: 46227.5 | B3: AMA-5095 | C3: GOO-128GB-BLU | D3: 350100007879405 | E3: GOO-128GB-BLU | F3: Unspecified | G3: 128GB | H3: MOBILE WHOLESALE LTD | I3: 1 | J3: 293.74 | K3: 406.06 | L3: =K3-J3 | M3: =L3*16.67% | N3: =K3/100*7 | O3: =N3*20% | P3: =N3*2% | Q3: =P3*20% | R3: 8 | S3: =R3*20% | T3: 1 | U3: =O3+Q3+S3 | V3: =L3-M3-N3-O3-P3-Q3-R3-S3-T3 | W3: =(V3-AC3)/J3*100 | X3: =M3-U3 | AD3: =V3-AC3
A4: 46226.5 | B4: AMA-5070 | C4: SAM-256GB-GRA | D4: 350100000554330 | E4: SAM-256GB-GRA | F4: GRAPHITE | G4: 256GB | H4: CELLHUB TRADING | I4: 1 | J4: 451.39 | K4: 574.19 | L4: =K4-J4 | M4: =L4*16.67% | N4: =K4/100*7 | O4: =N4*20% | P4: =N4*2% | Q4: =P4*20% | R4: 2 | S4: =R4*20% | T4: 1 | U4: =O4+Q4+S4 | V4: =L4-M4-N4-O4-P4-Q4-R4-S4-T4 | W4: =(V4-AC4)/J4*100 | X4: =M4-U4 | AD4: =V4-AC4
A5: 46225.5 | B5: AMA-5045 | C5: SAM-128GB-MID | D5: 350100000356355 | E5: SAM-128GB-MID | F5: MIDNIGHT | G5: 128GB | H5: CELLHUB TRADING | I5: 1 | J5: 237.5 | K5: 333.23 | L5: =K5-J5 | M5: =L5*16.67% | N5: =K5/100*7 | O5: =N5*20% | P5: =N5*2% | Q5: =P5*20% | R5: 8 | S5: =R5*20% | T5: 1 | U5: =O5+Q5+S5 | V5: =L5-M5-N5-O5-P5-Q5-R5-S5-T5 | W5: =(V5-AC5)/J5*100 | X5: =M5-U5 | AD5: =V5-AC5
A6: 46224.5 | B6: AMA-5020 | C6: IPH-256GB-GRE | D6: 350100000158380 | E6: iPhone | F6: GREEN | G6: 256GB | H6: CELLHUB TRADING | I6: 1 | J6: 469.17 | K6: 662.93 | L6: =K6-J6 | M6: =L6*16.67% | N6: =K6/100*7 | O6: =N6*20% | P6: =N6*2% | Q6: =P6*20% | R6: 6.3 | S6: =R6*20% | T6: 1 | U6: =O6+Q6+S6 | V6: =L6-M6-N6-O6-P6-Q6-R6-S6-T6 | W6: =(V6-AC6)/J6*100 | X6: =M6-U6 | AD6: =V6-AC6
A7: 46222.5 | B7: AMA-5090 | C7: IPH-128GB-GRA | D7: 350100007839810 | E7: iPhone | F7: Unspecified | G7: 128GB | H7: PHONEBOX DIRECT | I7: 1 | J7: 335.04 | K7: 494.65 | L7: =K7-J7 | M7: =L7*16.67% | N7: =K7/100*7 | O7: =N7*20% | P7: =N7*2% | Q7: =P7*20% | R7: 6.3 | S7: =R7*20% | T7: 1 | U7: =O7+Q7+S7 | V7: =L7-M7-N7-O7-P7-Q7-R7-S7-T7 | W7: =(V7-AC7)/J7*100 | X7: =M7-U7 | AD7: =V7-AC7
A8: 46221.5 | B8: AMA-5065 | C8: IPH-128GB-WHI | D8: 350100000514735 | E8: iPhone | F8: WHITE | G8: 128GB | H8: PHONEBOX DIRECT | I8: 1 | J8: 222.24 | K8: 294.66 | L8: =K8-J8 | M8: =L8*16.67% | N8: =K8/100*7 | O8: =N8*20% | P8: =N8*2% | Q8: =P8*20% | R8: 6.3 | S8: =R8*20% | T8: 1 | U8: =O8+Q8+S8 | V8: =L8-M8-N8-O8-P8-Q8-R8-S8-T8 | W8: =(V8-AC8)/J8*100 | X8: =M8-U8 | AD8: =V8-AC8
A9: 46220.5 | B9: AMA-5040 | C9: IPH-64GB-WHI | D9: 350100000316760 | E9: iPhone | F9: WHITE | G9: 64GB | H9: MOBILE WHOLESALE LTD | I9: 1 | J9: 192.93 | K9: 288.15 | L9: =K9-J9 | M9: =L9*16.67% | N9: =K9/100*7 | O9: =N9*20% | P9: =N9*2% | Q9: =P9*20% | R9: 8 | S9: =R9*20% | T9: 1 | U9: =O9+Q9+S9 | V9: =L9-M9-N9-O9-P9-Q9-R9-S9-T9 | W9: =(V9-AC9)/J9*100 | X9: =M9-U9 | AD9: =V9-AC9
A10: 46219.5 | B10: AMA-5015 | C10: GOO-128GB-BLA | D10: 350100000118785 | E10: GOO-128GB-BLA | F10: BLACK | G10: 128GB | H10: PHONEBOX DIRECT | I10: 1 | J10: 280.37 | K10: 392.6 | L10: =K10-J10 | M10: =L10*16.67% | N10: =K10/100*7 | O10: =N10*20% | P10: =N10*2% | Q10: =P10*20% | R10: 8 | S10: =R10*20% | T10: 1 | U10: =O10+Q10+S10 | V10: =L10-M10-N10-O10-P10-Q10-R10-S10-T10 | W10: =(V10-AC10)/J10*100 | X10: =M10-U10 | AD10: =V10-AC10
A11: 46217.5 | B11: AMA-5085 | C11: SAM-128GB-GRA | D11: 350100000673115 | E11: SAM-128GB-GRA | F11: GRAPHITE | G11: 128GB | H11: NORTHSIDE STOCK | I11: 1 | J11: 246.21 | K11: 319.55 | L11: =K11-J11 | M11: =L11*16.67% | N11: =K11/100*7 | O11: =N11*20% | P11: =N11*2% | Q11: =P11*20% | R11: 8 | S11: =R11*20% | T11: 1 | U11: =O11+Q11+S11 | V11: =L11-M11-N11-O11-P11-Q11-R11-S11-T11 | W11: =(V11-AC11)/J11*100 | X11: =M11-U11 | AD11: =V11-AC11
A12: 46216.5 | B12: AMA-5060 | C12: SAM-128GB-WHI | D12: 350100000483059 | E12: SAM-128GB-WHI | F12: WHITE | G12: 128GB | H12: MOBILE WHOLESALE LTD | I12: 1 | J12: 250.16 | K12: 335.89 | L12: =K12-J12 | M12: =L12*16.67% | N12: =K12/100*7 | O12: =N12*20% | P12: =N12*2% | Q12: =P12*20% | R12: 8 | S12: =R12*20% | T12: 1 | U12: =O12+Q12+S12 | V12: =L12-M12-N12-O12-P12-Q12-R12-S12-T12 | W12: =(V12-AC12)/J12*100 | X12: =M12-U12 | AD12: =V12-AC12
A13: 46215.5 | B13: AMA-5035 | C13: IPH-256GB-GRE | D13: 350100000277165 | E13: iPhone | F13: GREEN | G13: 256GB | H13: CELLHUB TRADING | I13: 1 | J13: 495.98 | K13: 737.52 | L13: =K13-J13 | M13: =L13*16.67% | N13: =K13/100*7 | O13: =N13*20% | P13: =N13*2% | Q13: =P13*20% | R13: 6.3 | S13: =R13*20% | T13: 1 | U13: =O13+Q13+S13 | V13: =L13-M13-N13-O13-P13-Q13-R13-S13-T13 | W13: =(V13-AC13)/J13*100 | X13: =M13-U13 | AD13: =V13-AC13
... A22: 46204.5 | B22: AMA-5000 | C22: IPH-128GB-GRA | D22: 350100000007919 | E22: iPhone | F22: GRAPHITE | G22: 128GB | H22: PHONEBOX DIRECT | I22: 1 | J22: 234.13 | K22: 319.21 | L22: =K22-J22 | M22: =L22*16.67% | N22: =K22/100*7 | O22: =N22*20% | P22: =N22*2% | Q22: =P22*20% | R22: 8 | S22: =R22*20% | T22: 1 | U22: =O22+Q22+S22 | V22: =L22-M22-N22-O22-P22-Q22-R22-S22-T22 | W22: =(V22-AC22)/J22*100 | X22: =M22-U22 | AD22: =V22-AC22
L23: =IF($K23="","",K23-J23) | M23: =IF($K23="","",L23*16.67%) | N23: =IF($K23="","",K23/100*7) | O23: =IF($K23="","",N23*20%) | P23: =IF($K23="","",N23*2%) | Q23: =IF($K23="","",P23*20%) | S23: =IF($K23="","",R23*20%) | T23: 1 | U23: =IF($K23="","",O23+Q23+S23) | V23: =IF($K23="","",L23-M23-N23-O23-P23-Q23-R23-S23-T23) | W23: =IF($K23="","",(V23-AC23)/J23*100) | X23: =IF($K23="","",M23-U23) | AD23: =IF($K23="","",V23-AC23)
L24: =IF($K24="","",K24-J24) | M24: =IF($K24="","",L24*16.67%) | N24: =IF($K24="","",K24/100*7) | O24: =IF($K24="","",N24*20%) | P24: =IF($K24="","",N24*2%) | Q24: =IF($K24="","",P24*20%) | S24: =IF($K24="","",R24*20%) | T24: 1 | U24: =IF($K24="","",O24+Q24+S24) | V24: =IF($K24="","",L24-M24-N24-O24-P24-Q24-R24-S24-T24) | W24: =IF($K24="","",(V24-AC24)/J24*100) | X24: =IF($K24="","",M24-U24) | AD24: =IF($K24="","",V24-AC24)
L25: =IF($K25="","",K25-J25) | M25: =IF($K25="","",L25*16.67%) | N25: =IF($K25="","",K25/100*7) | O25: =IF($K25="","",N25*20%) | P25: =IF($K25="","",N25*2%) | Q25: =IF($K25="","",P25*20%) | S25: =IF($K25="","",R25*20%) | T25: 1 | U25: =IF($K25="","",O25+Q25+S25) | V25: =IF($K25="","",L25-M25-N25-O25-P25-Q25-R25-S25-T25) | W25: =IF($K25="","",(V25-AC25)/J25*100) | X25: =IF($K25="","",M25-U25) | AD25: =IF($K25="","",V25-AC25)
L26: =IF($K26="","",K26-J26) | M26: =IF($K26="","",L26*16.67%) | N26: =IF($K26="","",K26/100*7) | O26: =IF($K26="","",N26*20%) | P26: =IF($K26="","",N26*2%) | Q26: =IF($K26="","",P26*20%) | S26: =IF($K26="","",R26*20%) | T26: 1 | U26: =IF($K26="","",O26+Q26+S26) | V26: =IF($K26="","",L26-M26-N26-O26-P26-Q26-R26-S26-T26) | W26: =IF($K26="","",(V26-AC26)/J26*100) | X26: =IF($K26="","",M26-U26) | AD26: =IF($K26="","",V26-AC26)
L27: =IF($K27="","",K27-J27) | M27: =IF($K27="","",L27*16.67%) | N27: =IF($K27="","",K27/100*7) | O27: =IF($K27="","",N27*20%) | P27: =IF($K27="","",N27*2%) | Q27: =IF($K27="","",P27*20%) | S27: =IF($K27="","",R27*20%) | T27: 1 | U27: =IF($K27="","",O27+Q27+S27) | V27: =IF($K27="","",L27-M27-N27-O27-P27-Q27-R27-S27-T27) | W27: =IF($K27="","",(V27-AC27)/J27*100) | X27: =IF($K27="","",M27-U27) | AD27: =IF($K27="","",V27-AC27)
L28: =IF($K28="","",K28-J28) | M28: =IF($K28="","",L28*16.67%) | N28: =IF($K28="","",K28/100*7) | O28: =IF($K28="","",N28*20%) | P28: =IF($K28="","",N28*2%) | Q28: =IF($K28="","",P28*20%) | S28: =IF($K28="","",R28*20%) | T28: 1 | U28: =IF($K28="","",O28+Q28+S28) | V28: =IF($K28="","",L28-M28-N28-O28-P28-Q28-R28-S28-T28) | W28: =IF($K28="","",(V28-AC28)/J28*100) | X28: =IF($K28="","",M28-U28) | AD28: =IF($K28="","",V28-AC28)
L29: =IF($K29="","",K29-J29) | M29: =IF($K29="","",L29*16.67%) | N29: =IF($K29="","",K29/100*7) | O29: =IF($K29="","",N29*20%) | P29: =IF($K29="","",N29*2%) | Q29: =IF($K29="","",P29*20%) | S29: =IF($K29="","",R29*20%) | T29: 1 | U29: =IF($K29="","",O29+Q29+S29) | V29: =IF($K29="","",L29-M29-N29-O29-P29-Q29-R29-S29-T29) | W29: =IF($K29="","",(V29-AC29)/J29*100) | X29: =IF($K29="","",M29-U29) | AD29: =IF($K29="","",V29-AC29)
L30: =IF($K30="","",K30-J30) | M30: =IF($K30="","",L30*16.67%) | N30: =IF($K30="","",K30/100*7) | O30: =IF($K30="","",N30*20%) | P30: =IF($K30="","",N30*2%) | Q30: =IF($K30="","",P30*20%) | S30: =IF($K30="","",R30*20%) | T30: 1 | U30: =IF($K30="","",O30+Q30+S30) | V30: =IF($K30="","",L30-M30-N30-O30-P30-Q30-R30-S30-T30) | W30: =IF($K30="","",(V30-AC30)/J30*100) | X30: =IF($K30="","",M30-U30) | AD30: =IF($K30="","",V30-AC30)
L31: =IF($K31="","",K31-J31) | M31: =IF($K31="","",L31*16.67%) | N31: =IF($K31="","",K31/100*7) | O31: =IF($K31="","",N31*20%) | P31: =IF($K31="","",N31*2%) | Q31: =IF($K31="","",P31*20%) | S31: =IF($K31="","",R31*20%) | T31: 1 | U31: =IF($K31="","",O31+Q31+S31) | V31: =IF($K31="","",L31-M31-N31-O31-P31-Q31-R31-S31-T31) | W31: =IF($K31="","",(V31-AC31)/J31*100) | X31: =IF($K31="","",M31-U31) | AD31: =IF($K31="","",V31-AC31)
L32: =IF($K32="","",K32-J32) | M32: =IF($K32="","",L32*16.67%) | N32: =IF($K32="","",K32/100*7) | O32: =IF($K32="","",N32*20%) | P32: =IF($K32="","",N32*2%) | Q32: =IF($K32="","",P32*20%) | S32: =IF($K32="","",R32*20%) | T32: 1 | U32: =IF($K32="","",O32+Q32+S32) | V32: =IF($K32="","",L32-M32-N32-O32-P32-Q32-R32-S32-T32) | W32: =IF($K32="","",(V32-AC32)/J32*100) | X32: =IF($K32="","",M32-U32) | AD32: =IF($K32="","",V32-AC32)
L33: =IF($K33="","",K33-J33) | M33: =IF($K33="","",L33*16.67%) | N33: =IF($K33="","",K33/100*7) | O33: =IF($K33="","",N33*20%) | P33: =IF($K33="","",N33*2%) | Q33: =IF($K33="","",P33*20%) | S33: =IF($K33="","",R33*20%) | T33: 1 | U33: =IF($K33="","",O33+Q33+S33) | V33: =IF($K33="","",L33-M33-N33-O33-P33-Q33-R33-S33-T33) | W33: =IF($K33="","",(V33-AC33)/J33*100) | X33: =IF($K33="","",M33-U33) | AD33: =IF($K33="","",V33-AC33)
L34: =IF($K34="","",K34-J34) | M34: =IF($K34="","",L34*16.67%) | N34: =IF($K34="","",K34/100*7) | O34: =IF($K34="","",N34*20%) | P34: =IF($K34="","",N34*2%) | Q34: =IF($K34="","",P34*20%) | S34: =IF($K34="","",R34*20%) | T34: 1 | U34: =IF($K34="","",O34+Q34+S34) | V34: =IF($K34="","",L34-M34-N34-O34-P34-Q34-R34-S34-T34) | W34: =IF($K34="","",(V34-AC34)/J34*100) | X34: =IF($K34="","",M34-U34) | AD34: =IF($K34="","",V34-AC34)
... L222: =IF($K222="","",K222-J222) | M222: =IF($K222="","",L222*16.67%) | N222: =IF($K222="","",K222/100*7) | O222: =IF($K222="","",N222*20%) | P222: =IF($K222="","",N222*2%) | Q222: =IF($K222="","",P222*20%) | S222: =IF($K222="","",R222*20%) | T222: 1 | U222: =IF($K222="","",O222+Q222+S222) | V222: =IF($K222="","",L222-M222-N222-O222-P222-Q222-R222-S222-T222) | W222: =IF($K222="","",(V222-AC222)/J222*100) | X222: =IF($K222="","",M222-U222) | AD222: =IF($K222="","",V222-AC222)
A223: TOTAL | I223: =SUM(I2:I222) | J223: =SUM(J2:J222) | K223: =SUM(K2:K222) | L223: =SUM(L2:L222) | M223: =SUM(M2:M222) | N223: =SUM(N2:N222) | O223: =SUM(O2:O222) | P223: =SUM(P2:P222) | ... V223: =SUM(V2:V222) | W223: =IFERROR((V223-AC223)/J223*100,0) | X223: =SUM(X2:X222) | Y223: =SUM(Y2:Y222) | Z223: =SUM(Z2:Z222) | AA223: =SUM(AA2:AA222) | AB223: =SUM(AB2:AB222) | AC223: =SUM(AC2:AC222) | AD223: =SUM(AD2:AD222)

Sheet BM
A1: Date | B1: Order Number | C1: SKU | D1: IMEI | E1: Model | F1: Colour | G1: Storage | H1: Supplier | I1: Quantity | J1: Payment Mode | K1: BP | L1: SP | M1: SP-BP | N1: Marginal Tax | O1: Commission | P1: Customer Care Fees | Q1: PSF | R1: Postage | S1: P. VAT | T1: Acc | U1: GP | V1: GP % | W1: Total VAT NTP | X1: Postage Loss | Y1: Fees Kept | Z1: Repair Cost | AA1: Supplier Credit | AB1: Return Cost | AC1: Net GP £ | AD1: Return Date | AE1: Outcome | AF1: Shipping Legs | AG1: Return Reason | AH1: Comments
A2: 46227.5 | B2: BM-5071 | C2: GOO-128GB-BLU | D2: 350100000562249 | E2: GOO-128GB-BLU | F2: BLUE | G2: 128GB | H2: PHONEBOX DIRECT | I2: 1 | J2: Klarna | K2: 264.82 | L2: 382.77 | M2: =L2-K2 | N2: =M2*16.67% | O2: =L2/100*11 | P2: 8.99 | Q2: 0 | R2: 6.3 | S2: =R2*20% | T2: 1 | U2: =M2-N2-O2-P2-Q2-R2-S2-T2 | V2: =(U2-AB2)/K2*100 | W2: =N2-S2 | AC2: =U2-AB2
A3: 46226.5 | B3: BM-5046 | C3: SAM-256GB-PUR | D3: 350100000364274 | E3: SAM-256GB-PUR | F3: PURPLE | G3: 256GB | H3: MOBILE WHOLESALE LTD | I3: 1 | J3: Klarna | K3: 453.75 | L3: 609.97 | M3: =L3-K3 | N3: =M3*16.67% | O3: =L3/100*11 | P3: 8.99 | Q3: 0 | R3: 2 | S3: =R3*20% | T3: 1 | U3: =M3-N3-O3-P3-Q3-R3-S3-T3 | V3: =(U3-AB3)/K3*100 | W3: =N3-S3 | AC3: =U3-AB3
A4: 46225.5 | B4: BM-5021 | C4: SAM-128GB-BLU | D4: 350100000166299 | E4: SAM-128GB-BLU | F4: BLUE | G4: 128GB | H4: NORTHSIDE STOCK | I4: 1 | J4: Klarna | K4: 246.31 | L4: 323.35 | M4: =L4-K4 | N4: =M4*16.67% | O4: =L4/100*11 | P4: 8.99 | Q4: 0 | R4: 8 | S4: =R4*20% | T4: 1 | U4: =M4-N4-O4-P4-Q4-R4-S4-T4 | V4: =(U4-AB4)/K4*100 | W4: =N4-S4 | AC4: =U4-AB4
A5: 46223.5 | B5: BM-5091 | C5: IPH-256GB-GRA | D5: 350100007847729 | E5: iPhone | F5: Unspecified | G5: 256GB | H5: NORTHSIDE STOCK | I5: 1 | J5: Klarna | K5: 530.25 | L5: 746.88 | M5: =L5-K5 | N5: =M5*16.67% | O5: =L5/100*11 | P5: 8.99 | Q5: 0 | R5: 8 | S5: =R5*20% | T5: 1 | U5: =M5-N5-O5-P5-Q5-R5-S5-T5 | V5: =(U5-AB5)/K5*100 | W5: =N5-S5 | AC5: =U5-AB5
A6: 46222.5 | B6: BM-5066 | C6: IPH-128GB-BLA | D6: 350100000522654 | E6: iPhone | F6: BLACK | G6: 128GB | H6: CELLHUB TRADING | I6: 1 | J6: Paypal | K6: 337.53 | L6: 453.07 | M6: =L6-K6 | N6: =M6*16.67% | O6: =L6/100*11 | P6: 8.99 | Q6: 0 | R6: 2 | S6: =R6*20% | T6: 1 | U6: =M6-N6-O6-P6-Q6-R6-S6-T6 | V6: =(U6-AB6)/K6*100 | W6: =N6-S6 | AC6: =U6-AB6
A7: 46221.5 | B7: BM-5041 | C7: IPH-128GB-MID | D7: 350100000324679 | E7: iPhone | F7: MIDNIGHT | G7: 128GB | H7: PHONEBOX DIRECT | I7: 1 | J7: Paypal | K7: 232.24 | L7: 310.64 | M7: =L7-K7 | N7: =M7*16.67% | O7: =L7/100*11 | P7: 8.99 | Q7: 0 | R7: 2 | S7: =R7*20% | T7: 1 | U7: =M7-N7-O7-P7-Q7-R7-S7-T7 | V7: =(U7-AB7)/K7*100 | W7: =N7-S7 | AC7: =U7-AB7
A8: 46220.5 | B8: BM-5016 | C8: IPH-64GB-MID | D8: 350100000126704 | E8: iPhone | F8: MIDNIGHT | G8: 64GB | H8: MOBILE WHOLESALE LTD | I8: 1 | J8: Card | K8: 212.15 | L8: 302.32 | M8: =L8-K8 | N8: =M8*16.67% | O8: =L8/100*11 | P8: 8.99 | Q8: 0 | R8: 8 | S8: =R8*20% | T8: 1 | U8: =M8-N8-O8-P8-Q8-R8-S8-T8 | V8: =(U8-AB8)/K8*100 | W8: =N8-S8 | AC8: =U8-AB8
A9: 46218.5 | B9: BM-5086 | C9: SAM-256GB-GRA | D9: 350100000681034 | E9: SAM-256GB-GRA | F9: GRAPHITE | G9: 256GB | H9: MOBILE WHOLESALE LTD | I9: 1 | J9: Card | K9: 413.46 | L9: 533.81 | M9: =L9-K9 | N9: =M9*16.67% | O9: =L9/100*11 | P9: 8.99 | Q9: 0 | R9: 8 | S9: =R9*20% | T9: 1 | U9: =M9-N9-O9-P9-Q9-R9-S9-T9 | V9: =(U9-AB9)/K9*100 | W9: =N9-S9 | AC9: =U9-AB9
A10: 46217.5 | B10: BM-5061 | C10: SAM-128GB-WHI | D10: 350100000483059 | E10: SAM-128GB-WHI | F10: WHITE | G10: 128GB | H10: MOBILE WHOLESALE LTD | I10: 1 | J10: Paypal | K10: 250.16 | L10: 352.23 | M10: =L10-K10 | N10: =M10*16.67% | O10: =L10/100*11 | P10: 8.99 | Q10: 0 | R10: 8 | S10: =R10*20% | T10: 1 | U10: =M10-N10-O10-P10-Q10-R10-S10-T10 | V10: =(U10-AB10)/K10*100 | W10: =N10-S10 | AC10: =U10-AB10
A11: 46216.5 | B11: BM-5036 | C11: SAM-128GB-GRE | D11: 350100000293003 | E11: SAM-128GB-GRE | F11: GREEN | G11: 128GB | H11: MOBILE WHOLESALE LTD | I11: 1 | J11: Klarna | K11: 262.94 | L11: 388.08 | M11: =L11-K11 | N11: =M11*16.67% | O11: =L11/100*11 | P11: 8.99 | Q11: 0 | R11: 8 | S11: =R11*20% | T11: 1 | U11: =M11-N11-O11-P11-Q11-R11-S11-T11 | V11: =(U11-AB11)/K11*100 | W11: =N11-S11 | AC11: =U11-AB11
A12: 46215.5 | B12: BM-5011 | C12: IPH-256GB-BLA | D12: 350100000087109 | E12: iPhone | F12: BLACK | G12: 256GB | H12: MOBILE WHOLESALE LTD | I12: 1 | J12: Card | K12: 514.23 | L12: 704.32 | M12: =L12-K12 | N12: =M12*16.67% | O12: =L12/100*11 | P12: 8.99 | Q12: 0 | R12: 2 | S12: =R12*20% | T12: 1 | U12: =M12-N12-O12-P12-Q12-R12-S12-T12 | V12: =(U12-AB12)/K12*100 | W12: =N12-S12 | AC12: =U12-AB12
A13: 46213.5 | B13: BM-5081 | C13: IPH-128GB-PUR | D13: 350100000641439 | E13: iPhone | F13: PURPLE | G13: 128GB | H13: PHONEBOX DIRECT | I13: 1 | J13: Klarna | K13: 231.07 | L13: 317.79 | M13: =L13-K13 | N13: =M13*16.67% | O13: =L13/100*11 | P13: 8.99 | Q13: 0 | R13: 8 | S13: =R13*20% | T13: 1 | U13: =M13-N13-O13-P13-Q13-R13-S13-T13 | V13: =(U13-AB13)/K13*100 | W13: =N13-S13 | AC13: =U13-AB13
... A21: 46204.5 | B21: BM-5096 | C21: IPH-128GB-GRA | D21: 350100007887324 | E21: iPhone | F21: Unspecified | G21: 128GB | H21: PHONEBOX DIRECT | I21: 1 | J21: Klarna | K21: 223.04 | L21: 298.35 | M21: =L21-K21 | N21: =M21*16.67% | O21: =L21/100*11 | P21: 8.99 | Q21: 0 | R21: 6.3 | S21: =R21*20% | T21: 1 | U21: =M21-N21-O21-P21-Q21-R21-S21-T21 | V21: =(U21-AB21)/K21*100 | W21: =N21-S21 | AC21: =U21-AB21
M22: =IF($L22="","",L22-K22) | N22: =IF($L22="","",M22*16.67%) | O22: =IF($L22="","",L22/100*11) | P22: 8.99 | Q22: =IF($L22="","",L22*1%) | S22: =IF($L22="","",R22*20%) | T22: 1 | U22: =IF($L22="","",M22-N22-O22-P22-Q22-R22-S22-T22) | V22: =IF($L22="","",(U22-AB22)/K22*100) | W22: =IF($L22="","",N22-S22) | AC22: =IF($L22="","",U22-AB22)
M23: =IF($L23="","",L23-K23) | N23: =IF($L23="","",M23*16.67%) | O23: =IF($L23="","",L23/100*11) | P23: 8.99 | Q23: =IF($L23="","",L23*1%) | S23: =IF($L23="","",R23*20%) | T23: 1 | U23: =IF($L23="","",M23-N23-O23-P23-Q23-R23-S23-T23) | V23: =IF($L23="","",(U23-AB23)/K23*100) | W23: =IF($L23="","",N23-S23) | AC23: =IF($L23="","",U23-AB23)
M24: =IF($L24="","",L24-K24) | N24: =IF($L24="","",M24*16.67%) | O24: =IF($L24="","",L24/100*11) | P24: 8.99 | Q24: =IF($L24="","",L24*1%) | S24: =IF($L24="","",R24*20%) | T24: 1 | U24: =IF($L24="","",M24-N24-O24-P24-Q24-R24-S24-T24) | V24: =IF($L24="","",(U24-AB24)/K24*100) | W24: =IF($L24="","",N24-S24) | AC24: =IF($L24="","",U24-AB24)
M25: =IF($L25="","",L25-K25) | N25: =IF($L25="","",M25*16.67%) | O25: =IF($L25="","",L25/100*11) | P25: 8.99 | Q25: =IF($L25="","",L25*1%) | S25: =IF($L25="","",R25*20%) | T25: 1 | U25: =IF($L25="","",M25-N25-O25-P25-Q25-R25-S25-T25) | V25: =IF($L25="","",(U25-AB25)/K25*100) | W25: =IF($L25="","",N25-S25) | AC25: =IF($L25="","",U25-AB25)
M26: =IF($L26="","",L26-K26) | N26: =IF($L26="","",M26*16.67%) | O26: =IF($L26="","",L26/100*11) | P26: 8.99 | Q26: =IF($L26="","",L26*1%) | S26: =IF($L26="","",R26*20%) | T26: 1 | U26: =IF($L26="","",M26-N26-O26-P26-Q26-R26-S26-T26) | V26: =IF($L26="","",(U26-AB26)/K26*100) | W26: =IF($L26="","",N26-S26) | AC26: =IF($L26="","",U26-AB26)
M27: =IF($L27="","",L27-K27) | N27: =IF($L27="","",M27*16.67%) | O27: =IF($L27="","",L27/100*11) | P27: 8.99 | Q27: =IF($L27="","",L27*1%) | S27: =IF($L27="","",R27*20%) | T27: 1 | U27: =IF($L27="","",M27-N27-O27-P27-Q27-R27-S27-T27) | V27: =IF($L27="","",(U27-AB27)/K27*100) | W27: =IF($L27="","",N27-S27) | AC27: =IF($L27="","",U27-AB27)
M28: =IF($L28="","",L28-K28) | N28: =IF($L28="","",M28*16.67%) | O28: =IF($L28="","",L28/100*11) | P28: 8.99 | Q28: =IF($L28="","",L28*1%) | S28: =IF($L28="","",R28*20%) | T28: 1 | U28: =IF($L28="","",M28-N28-O28-P28-Q28-R28-S28-T28) | V28: =IF($L28="","",(U28-AB28)/K28*100) | W28: =IF($L28="","",N28-S28) | AC28: =IF($L28="","",U28-AB28)
M29: =IF($L29="","",L29-K29) | N29: =IF($L29="","",M29*16.67%) | O29: =IF($L29="","",L29/100*11) | P29: 8.99 | Q29: =IF($L29="","",L29*1%) | S29: =IF($L29="","",R29*20%) | T29: 1 | U29: =IF($L29="","",M29-N29-O29-P29-Q29-R29-S29-T29) | V29: =IF($L29="","",(U29-AB29)/K29*100) | W29: =IF($L29="","",N29-S29) | AC29: =IF($L29="","",U29-AB29)
M30: =IF($L30="","",L30-K30) | N30: =IF($L30="","",M30*16.67%) | O30: =IF($L30="","",L30/100*11) | P30: 8.99 | Q30: =IF($L30="","",L30*1%) | S30: =IF($L30="","",R30*20%) | T30: 1 | U30: =IF($L30="","",M30-N30-O30-P30-Q30-R30-S30-T30) | V30: =IF($L30="","",(U30-AB30)/K30*100) | W30: =IF($L30="","",N30-S30) | AC30: =IF($L30="","",U30-AB30)
M31: =IF($L31="","",L31-K31) | N31: =IF($L31="","",M31*16.67%) | O31: =IF($L31="","",L31/100*11) | P31: 8.99 | Q31: =IF($L31="","",L31*1%) | S31: =IF($L31="","",R31*20%) | T31: 1 | U31: =IF($L31="","",M31-N31-O31-P31-Q31-R31-S31-T31) | V31: =IF($L31="","",(U31-AB31)/K31*100) | W31: =IF($L31="","",N31-S31) | AC31: =IF($L31="","",U31-AB31)
M32: =IF($L32="","",L32-K32) | N32: =IF($L32="","",M32*16.67%) | O32: =IF($L32="","",L32/100*11) | P32: 8.99 | Q32: =IF($L32="","",L32*1%) | S32: =IF($L32="","",R32*20%) | T32: 1 | U32: =IF($L32="","",M32-N32-O32-P32-Q32-R32-S32-T32) | V32: =IF($L32="","",(U32-AB32)/K32*100) | W32: =IF($L32="","",N32-S32) | AC32: =IF($L32="","",U32-AB32)
M33: =IF($L33="","",L33-K33) | N33: =IF($L33="","",M33*16.67%) | O33: =IF($L33="","",L33/100*11) | P33: 8.99 | Q33: =IF($L33="","",L33*1%) | S33: =IF($L33="","",R33*20%) | T33: 1 | U33: =IF($L33="","",M33-N33-O33-P33-Q33-R33-S33-T33) | V33: =IF($L33="","",(U33-AB33)/K33*100) | W33: =IF($L33="","",N33-S33) | AC33: =IF($L33="","",U33-AB33)
... M221: =IF($L221="","",L221-K221) | N221: =IF($L221="","",M221*16.67%) | O221: =IF($L221="","",L221/100*11) | P221: 8.99 | Q221: =IF($L221="","",L221*1%) | S221: =IF($L221="","",R221*20%) | T221: 1 | U221: =IF($L221="","",M221-N221-O221-P221-Q221-R221-S221-T221) | V221: =IF($L221="","",(U221-AB221)/K221*100) | W221: =IF($L221="","",N221-S221) | AC221: =IF($L221="","",U221-AB221)
A222: TOTAL | I222: =SUM(I2:I221) | K222: =SUM(K2:K221) | L222: =SUM(L2:L221) | M222: =SUM(M2:M221) | N222: =SUM(N2:N221) | O222: =SUM(O2:O221) | P222: =SUM(P2:P221) | Q222: =SUM(Q2:Q221) | R222: =SUM(R2:R221) | ... U222: =SUM(U2:U221) | V222: =IFERROR((U222-AB222)/K222*100,0) | W222: =SUM(W2:W221) | X222: =SUM(X2:X221) | Y222: =SUM(Y2:Y221) | Z222: =SUM(Z2:Z221) | AA222: =SUM(AA2:AA221) | AB222: =SUM(AB2:AB221) | AC222: =SUM(AC2:AC221)

Sheet EBAY
A1: Date | B1: Order Number | C1: SKU | D1: IMEI | E1: Model | F1: Colour | G1: Storage | H1: Supplier | I1: Units | J1: BP | K1: SP | L1: SP-BP | M1: Marginal Tax | N1: Commission | O1: ROF | P1: FVF | Q1: VAT | R1: T.COM | S1: Postage | T1: P. VAT | U1: Marketing | V1: M. VAT | W1: Acc | X1: Total VAT | Y1: GP | Z1: GP % | AA1: Total VAT NTP | AB1: Postage Loss | AC1: Fees Kept | AD1: Repair Cost | AE1: Supplier Credit | AF1: Return Cost | AG1: Net GP £ | AH1: Return Date | AI1: Outcome | AJ1: Shipping Legs | AK1: Return Reason | AL1: Comments
A2: 46227.5 | B2: EBA-5047 | C2: GOO-128GB-GRA | D2: 350100000372193 | E2: GOO-128GB-GRA | F2: GRAPHITE | G2: 128GB | H2: CELLHUB TRADING | I2: 1 | J2: 256.93 | K2: 344.13 | L2: =K2-J2 | M2: =L2*16.67% | N2: =(K2*6.9%)-(K2*6.9%)*10% | O2: =K2*0.35% | P2: 0.4 | Q2: =(N2+O2+P2)*20% | R2: =N2+O2+P2+Q2 | S2: 8 | T2: 0 | U2: 0 | V2: =U2*20% | W2: 1 | X2: =Q2+T2+V2 | Y2: =L2-M2-R2-S2-T2-U2-V2-W2 | Z2: =(Y2-AF2)/J2*100 | AA2: =M2-X2 | AG2: =Y2-AF2
A3: 46226.5 | B3: EBA-5022 | C3: SAM-256GB-MID | D3: 350100000174218 | E3: SAM-256GB-MID | F3: MIDNIGHT | G3: 256GB | H3: CELLHUB TRADING | I3: 1 | J3: 449.53 | K3: 632.67 | L3: =K3-J3 | M3: =L3*16.67% | N3: =(K3*6.9%)-(K3*6.9%)*10% | O3: =K3*0.35% | P3: 0.4 | Q3: =(N3+O3+P3)*20% | R3: =N3+O3+P3+Q3 | S3: 8 | T3: 0 | U3: 0 | V3: =U3*20% | W3: 1 | X3: =Q3+T3+V3 | Y3: =L3-M3-R3-S3-T3-U3-V3-W3 | Z3: =(Y3-AF3)/J3*100 | AA3: =M3-X3 | AG3: =Y3-AF3
A4: 46224.5 | B4: EBA-5092 | C4: IPH-256GB-GRA | D4: 350100007855648 | E4: iPhone | F4: Unspecified | G4: 256GB | H4: PHONEBOX DIRECT | I4: 1 | J4: 462.92 | K4: 686.89 | L4: =K4-J4 | M4: =L4*16.67% | N4: =(K4*6.9%)-(K4*6.9%)*10% | O4: =K4*0.35% | P4: 0.4 | Q4: =(N4+O4+P4)*20% | R4: =N4+O4+P4+Q4 | S4: 8 | T4: 0 | U4: 0 | V4: =U4*20% | W4: 1 | X4: =Q4+T4+V4 | Y4: =L4-M4-R4-S4-T4-U4-V4-W4 | Z4: =(Y4-AF4)/J4*100 | AA4: =M4-X4 | AG4: =Y4-AF4
A5: 46223.5 | B5: EBA-5067 | C5: IPH-256GB-GRA | D5: 350100000530573 | E5: iPhone | F5: GRAPHITE | G5: 256GB | H5: CELLHUB TRADING | I5: 1 | J5: 500.16 | K5: 745.1 | L5: =K5-J5 | M5: =L5*16.67% | N5: =(K5*6.9%)-(K5*6.9%)*10% | O5: =K5*0.35% | P5: 0.4 | Q5: =(N5+O5+P5)*20% | R5: =N5+O5+P5+Q5 | S5: 8 | T5: 0 | U5: 0 | V5: =U5*20% | W5: 1 | X5: =Q5+T5+V5 | Y5: =L5-M5-R5-S5-T5-U5-V5-W5 | Z5: =(Y5-AF5)/J5*100 | AA5: =M5-X5 | AG5: =Y5-AF5
A6: 46222.5 | B6: EBA-5042 | C6: IPH-128GB-WHI | D6: 350100000332598 | E6: iPhone | F6: WHITE | G6: 128GB | H6: NORTHSIDE STOCK | I6: 1 | J6: 334.64 | K6: 432.05 | L6: =K6-J6 | M6: =L6*16.67% | N6: =(K6*6.9%)-(K6*6.9%)*10% | O6: =K6*0.35% | P6: 0.4 | Q6: =(N6+O6+P6)*20% | R6: =N6+O6+P6+Q6 | S6: 2 | T6: 0 | U6: 0 | V6: =U6*20% | W6: 1 | X6: =Q6+T6+V6 | Y6: =L6-M6-R6-S6-T6-U6-V6-W6 | Z6: =(Y6-AF6)/J6*100 | AA6: =M6-X6 | AG6: =Y6-AF6
A7: 46221.5 | B7: EBA-5017 | C7: IPH-128GB-GRA | D7: 350100000134623 | E7: iPhone | F7: GRAPHITE | G7: 128GB | H7: CELLHUB TRADING | I7: 1 | J7: 219.35 | K7: 322.18 | L7: =K7-J7 | M7: =L7*16.67% | N7: =(K7*6.9%)-(K7*6.9%)*10% | O7: =K7*0.35% | P7: 0.4 | Q7: =(N7+O7+P7)*20% | R7: =N7+O7+P7+Q7 | S7: 2 | T7: 0 | U7: 0 | V7: =U7*20% | W7: 1 | X7: =Q7+T7+V7 | Y7: =L7-M7-R7-S7-T7-U7-V7-W7 | Z7: =(Y7-AF7)/J7*100 | AA7: =M7-X7 | AG7: =Y7-AF7
A8: 46219.5 | B8: EBA-5087 | C8: GOO-128GB-STA | D8: 350100000688953 | E8: GOO-128GB-STA | F8: STARLIGHT | G8: 128GB | H8: PHONEBOX DIRECT | I8: 1 | J8: 275.49 | K8: 405.63 | L8: =K8-J8 | M8: =L8*16.67% | N8: =(K8*6.9%)-(K8*6.9%)*10% | O8: =K8*0.35% | P8: 0.4 | Q8: =(N8+O8+P8)*20% | R8: =N8+O8+P8+Q8 | S8: 8 | T8: 0 | U8: 0 | V8: =U8*20% | W8: 1 | X8: =Q8+T8+V8 | Y8: =L8-M8-R8-S8-T8-U8-V8-W8 | Z8: =(Y8-AF8)/J8*100 | AA8: =M8-X8 | AG8: =Y8-AF8
A9: 46218.5 | B9: EBA-5062 | C9: SAM-256GB-BLU | D9: 350100000490978 | E9: SAM-256GB-BLU | F9: BLUE | G9: 256GB | H9: CELLHUB TRADING | I9: 1 | J9: 431.55 | K9: 555.17 | L9: =K9-J9 | M9: =L9*16.67% | N9: =(K9*6.9%)-(K9*6.9%)*10% | O9: =K9*0.35% | P9: 0.4 | Q9: =(N9+O9+P9)*20% | R9: =N9+O9+P9+Q9 | S9: 8 | T9: 0 | U9: 0 | V9: =U9*20% | W9: 1 | X9: =Q9+T9+V9 | Y9: =L9-M9-R9-S9-T9-U9-V9-W9 | Z9: =(Y9-AF9)/J9*100 | AA9: =M9-X9 | AG9: =Y9-AF9
A10: 46217.5 | B10: EBA-5037 | C10: SAM-128GB-GRE | D10: 350100000293003 | E10: SAM-128GB-GRE | F10: GREEN | G10: 128GB | H10: MOBILE WHOLESALE LTD | I10: 1 | J10: 262.94 | K10: 393.16 | L10: =K10-J10 | M10: =L10*16.67% | N10: =(K10*6.9%)-(K10*6.9%)*10% | O10: =K10*0.35% | P10: 0.4 | Q10: =(N10+O10+P10)*20% | R10: =N10+O10+P10+Q10 | S10: 2 | T10: 0 | U10: 0 | V10: =U10*20% | W10: 1 | X10: =Q10+T10+V10 | Y10: =L10-M10-R10-S10-T10-U10-V10-W10 | Z10: =(Y10-AF10)/J10*100 | AA10: =M10-X10 | AG10: =Y10-AF10
A11: 46216.5 | B11: EBA-5012 | C11: SAM-128GB-BLU | D11: 350100000102947 | E11: SAM-128GB-BLU | F11: BLUE | G11: 128GB | H11: MOBILE WHOLESALE LTD | I11: 1 | J11: 230.57 | K11: 319.34 | L11: =K11-J11 | M11: =L11*16.67% | N11: =(K11*6.9%)-(K11*6.9%)*10% | O11: =K11*0.35% | P11: 0.4 | Q11: =(N11+O11+P11)*20% | R11: =N11+O11+P11+Q11 | S11: 8 | T11: 0 | U11: 0 | V11: =U11*20% | W11: 1 | X11: =Q11+T11+V11 | Y11: =L11-M11-R11-S11-T11-U11-V11-W11 | Z11: =(Y11-AF11)/J11*100 | AA11: =M11-X11 | AG11: =Y11-AF11
A12: 46214.5 | B12: EBA-5082 | C12: IPH-128GB-MID | D12: 350100000649358 | E12: iPhone | F12: MIDNIGHT | G12: 128GB | H12: PHONEBOX DIRECT | I12: 1 | J12: 315.22 | K12: 397.26 | L12: =K12-J12 | M12: =L12*16.67% | N12: =(K12*6.9%)-(K12*6.9%)*10% | O12: =K12*0.35% | P12: 0.4 | Q12: =(N12+O12+P12)*20% | R12: =N12+O12+P12+Q12 | S12: 8 | T12: 0 | U12: 0 | V12: =U12*20% | W12: 1 | X12: =Q12+T12+V12 | Y12: =L12-M12-R12-S12-T12-U12-V12-W12 | Z12: =(Y12-AF12)/J12*100 | AA12: =M12-X12 | AG12: =Y12-AF12
A13: 46213.5 | B13: EBA-5057 | C13: IPH-128GB-BLA | D13: 350100000451383 | E13: iPhone | F13: BLACK | G13: 128GB | H13: PHONEBOX DIRECT | I13: 1 | J13: 218.51 | K13: 303.91 | L13: =K13-J13 | M13: =L13*16.67% | N13: =(K13*6.9%)-(K13*6.9%)*10% | O13: =K13*0.35% | P13: 0.4 | Q13: =(N13+O13+P13)*20% | R13: =N13+O13+P13+Q13 | S13: 8 | T13: 0 | U13: 0 | V13: =U13*20% | W13: 1 | X13: =Q13+T13+V13 | Y13: =L13-M13-R13-S13-T13-U13-V13-W13 | Z13: =(Y13-AF13)/J13*100 | AA13: =M13-X13 | AG13: =Y13-AF13
... A21: 46204.5 | B21: EBA-5072 | C21: IPH-128GB-MID | D21: 350100000578087 | E21: iPhone | F21: MIDNIGHT | G21: 128GB | H21: NORTHSIDE STOCK | I21: 1 | J21: 222.91 | K21: 314.64 | L21: =K21-J21 | M21: =L21*16.67% | N21: =(K21*6.9%)-(K21*6.9%)*10% | O21: =K21*0.35% | P21: 0.4 | Q21: =(N21+O21+P21)*20% | R21: =N21+O21+P21+Q21 | S21: 6.3 | T21: 0 | U21: 0 | V21: =U21*20% | W21: 1 | X21: =Q21+T21+V21 | Y21: =L21-M21-R21-S21-T21-U21-V21-W21 | Z21: =(Y21-AF21)/J21*100 | AA21: =M21-X21 | AG21: =Y21-AF21
L22: =IF($K22="","",K22-J22) | M22: =IF($K22="","",L22*16.67%) | N22: =IF($K22="","",(K22*6.9%)-(K22*6.9%)*10%) | O22: =IF($K22="","",K22*0.35%) | P22: 0.4 | Q22: =IF($K22="","",(N22+O22+P22)*20%) | R22: =IF($K22="","",N22+O22+P22+Q22) | V22: =IF($K22="","",U22*20%) | W22: 1 | X22: =IF($K22="","",Q22+T22+V22) | Y22: =IF($K22="","",L22-M22-R22-S22-T22-U22-V22-W22) | Z22: =IF($K22="","",(Y22-AF22)/J22*100) | AA22: =IF($K22="","",M22-X22) | AG22: =IF($K22="","",Y22-AF22)
L23: =IF($K23="","",K23-J23) | M23: =IF($K23="","",L23*16.67%) | N23: =IF($K23="","",(K23*6.9%)-(K23*6.9%)*10%) | O23: =IF($K23="","",K23*0.35%) | P23: 0.4 | Q23: =IF($K23="","",(N23+O23+P23)*20%) | R23: =IF($K23="","",N23+O23+P23+Q23) | V23: =IF($K23="","",U23*20%) | W23: 1 | X23: =IF($K23="","",Q23+T23+V23) | Y23: =IF($K23="","",L23-M23-R23-S23-T23-U23-V23-W23) | Z23: =IF($K23="","",(Y23-AF23)/J23*100) | AA23: =IF($K23="","",M23-X23) | AG23: =IF($K23="","",Y23-AF23)
L24: =IF($K24="","",K24-J24) | M24: =IF($K24="","",L24*16.67%) | N24: =IF($K24="","",(K24*6.9%)-(K24*6.9%)*10%) | O24: =IF($K24="","",K24*0.35%) | P24: 0.4 | Q24: =IF($K24="","",(N24+O24+P24)*20%) | R24: =IF($K24="","",N24+O24+P24+Q24) | V24: =IF($K24="","",U24*20%) | W24: 1 | X24: =IF($K24="","",Q24+T24+V24) | Y24: =IF($K24="","",L24-M24-R24-S24-T24-U24-V24-W24) | Z24: =IF($K24="","",(Y24-AF24)/J24*100) | AA24: =IF($K24="","",M24-X24) | AG24: =IF($K24="","",Y24-AF24)
L25: =IF($K25="","",K25-J25) | M25: =IF($K25="","",L25*16.67%) | N25: =IF($K25="","",(K25*6.9%)-(K25*6.9%)*10%) | O25: =IF($K25="","",K25*0.35%) | P25: 0.4 | Q25: =IF($K25="","",(N25+O25+P25)*20%) | R25: =IF($K25="","",N25+O25+P25+Q25) | V25: =IF($K25="","",U25*20%) | W25: 1 | X25: =IF($K25="","",Q25+T25+V25) | Y25: =IF($K25="","",L25-M25-R25-S25-T25-U25-V25-W25) | Z25: =IF($K25="","",(Y25-AF25)/J25*100) | AA25: =IF($K25="","",M25-X25) | AG25: =IF($K25="","",Y25-AF25)
L26: =IF($K26="","",K26-J26) | M26: =IF($K26="","",L26*16.67%) | N26: =IF($K26="","",(K26*6.9%)-(K26*6.9%)*10%) | O26: =IF($K26="","",K26*0.35%) | P26: 0.4 | Q26: =IF($K26="","",(N26+O26+P26)*20%) | R26: =IF($K26="","",N26+O26+P26+Q26) | V26: =IF($K26="","",U26*20%) | W26: 1 | X26: =IF($K26="","",Q26+T26+V26) | Y26: =IF($K26="","",L26-M26-R26-S26-T26-U26-V26-W26) | Z26: =IF($K26="","",(Y26-AF26)/J26*100) | AA26: =IF($K26="","",M26-X26) | AG26: =IF($K26="","",Y26-AF26)
L27: =IF($K27="","",K27-J27) | M27: =IF($K27="","",L27*16.67%) | N27: =IF($K27="","",(K27*6.9%)-(K27*6.9%)*10%) | O27: =IF($K27="","",K27*0.35%) | P27: 0.4 | Q27: =IF($K27="","",(N27+O27+P27)*20%) | R27: =IF($K27="","",N27+O27+P27+Q27) | V27: =IF($K27="","",U27*20%) | W27: 1 | X27: =IF($K27="","",Q27+T27+V27) | Y27: =IF($K27="","",L27-M27-R27-S27-T27-U27-V27-W27) | Z27: =IF($K27="","",(Y27-AF27)/J27*100) | AA27: =IF($K27="","",M27-X27) | AG27: =IF($K27="","",Y27-AF27)
L28: =IF($K28="","",K28-J28) | M28: =IF($K28="","",L28*16.67%) | N28: =IF($K28="","",(K28*6.9%)-(K28*6.9%)*10%) | O28: =IF($K28="","",K28*0.35%) | P28: 0.4 | Q28: =IF($K28="","",(N28+O28+P28)*20%) | R28: =IF($K28="","",N28+O28+P28+Q28) | V28: =IF($K28="","",U28*20%) | W28: 1 | X28: =IF($K28="","",Q28+T28+V28) | Y28: =IF($K28="","",L28-M28-R28-S28-T28-U28-V28-W28) | Z28: =IF($K28="","",(Y28-AF28)/J28*100) | AA28: =IF($K28="","",M28-X28) | AG28: =IF($K28="","",Y28-AF28)
L29: =IF($K29="","",K29-J29) | M29: =IF($K29="","",L29*16.67%) | N29: =IF($K29="","",(K29*6.9%)-(K29*6.9%)*10%) | O29: =IF($K29="","",K29*0.35%) | P29: 0.4 | Q29: =IF($K29="","",(N29+O29+P29)*20%) | R29: =IF($K29="","",N29+O29+P29+Q29) | V29: =IF($K29="","",U29*20%) | W29: 1 | X29: =IF($K29="","",Q29+T29+V29) | Y29: =IF($K29="","",L29-M29-R29-S29-T29-U29-V29-W29) | Z29: =IF($K29="","",(Y29-AF29)/J29*100) | AA29: =IF($K29="","",M29-X29) | AG29: =IF($K29="","",Y29-AF29)
L30: =IF($K30="","",K30-J30) | M30: =IF($K30="","",L30*16.67%) | N30: =IF($K30="","",(K30*6.9%)-(K30*6.9%)*10%) | O30: =IF($K30="","",K30*0.35%) | P30: 0.4 | Q30: =IF($K30="","",(N30+O30+P30)*20%) | R30: =IF($K30="","",N30+O30+P30+Q30) | V30: =IF($K30="","",U30*20%) | W30: 1 | X30: =IF($K30="","",Q30+T30+V30) | Y30: =IF($K30="","",L30-M30-R30-S30-T30-U30-V30-W30) | Z30: =IF($K30="","",(Y30-AF30)/J30*100) | AA30: =IF($K30="","",M30-X30) | AG30: =IF($K30="","",Y30-AF30)
L31: =IF($K31="","",K31-J31) | M31: =IF($K31="","",L31*16.67%) | N31: =IF($K31="","",(K31*6.9%)-(K31*6.9%)*10%) | O31: =IF($K31="","",K31*0.35%) | P31: 0.4 | Q31: =IF($K31="","",(N31+O31+P31)*20%) | R31: =IF($K31="","",N31+O31+P31+Q31) | V31: =IF($K31="","",U31*20%) | W31: 1 | X31: =IF($K31="","",Q31+T31+V31) | Y31: =IF($K31="","",L31-M31-R31-S31-T31-U31-V31-W31) | Z31: =IF($K31="","",(Y31-AF31)/J31*100) | AA31: =IF($K31="","",M31-X31) | AG31: =IF($K31="","",Y31-AF31)
L32: =IF($K32="","",K32-J32) | M32: =IF($K32="","",L32*16.67%) | N32: =IF($K32="","",(K32*6.9%)-(K32*6.9%)*10%) | O32: =IF($K32="","",K32*0.35%) | P32: 0.4 | Q32: =IF($K32="","",(N32+O32+P32)*20%) | R32: =IF($K32="","",N32+O32+P32+Q32) | V32: =IF($K32="","",U32*20%) | W32: 1 | X32: =IF($K32="","",Q32+T32+V32) | Y32: =IF($K32="","",L32-M32-R32-S32-T32-U32-V32-W32) | Z32: =IF($K32="","",(Y32-AF32)/J32*100) | AA32: =IF($K32="","",M32-X32) | AG32: =IF($K32="","",Y32-AF32)
L33: =IF($K33="","",K33-J33) | M33: =IF($K33="","",L33*16.67%) | N33: =IF($K33="","",(K33*6.9%)-(K33*6.9%)*10%) | O33: =IF($K33="","",K33*0.35%) | P33: 0.4 | Q33: =IF($K33="","",(N33+O33+P33)*20%) | R33: =IF($K33="","",N33+O33+P33+Q33) | V33: =IF($K33="","",U33*20%) | W33: 1 | X33: =IF($K33="","",Q33+T33+V33) | Y33: =IF($K33="","",L33-M33-R33-S33-T33-U33-V33-W33) | Z33: =IF($K33="","",(Y33-AF33)/J33*100) | AA33: =IF($K33="","",M33-X33) | AG33: =IF($K33="","",Y33-AF33)
... L221: =IF($K221="","",K221-J221) | M221: =IF($K221="","",L221*16.67%) | N221: =IF($K221="","",(K221*6.9%)-(K221*6.9%)*10%) | O221: =IF($K221="","",K221*0.35%) | P221: 0.4 | Q221: =IF($K221="","",(N221+O221+P221)*20%) | R221: =IF($K221="","",N221+O221+P221+Q221) | V221: =IF($K221="","",U221*20%) | W221: 1 | X221: =IF($K221="","",Q221+T221+V221) | Y221: =IF($K221="","",L221-M221-R221-S221-T221-U221-V221-W221) | Z221: =IF($K221="","",(Y221-AF221)/J221*100) | AA221: =IF($K221="","",M221-X221) | AG221: =IF($K221="","",Y221-AF221)
A222: TOTAL | I222: =SUM(I2:I221) | J222: =SUM(J2:J221) | K222: =SUM(K2:K221) | L222: =SUM(L2:L221) | M222: =SUM(M2:M221) | N222: =SUM(N2:N221) | O222: =SUM(O2:O221) | P222: =SUM(P2:P221) | ... Y222: =SUM(Y2:Y221) | Z222: =IFERROR((Y222-AF222)/K222*100,0) | AA222: =SUM(AA2:AA221) | AB222: =SUM(AB2:AB221) | AC222: =SUM(AC2:AC221) | AD222: =SUM(AD2:AD221) | AE222: =SUM(AE2:AE221) | AF222: =SUM(AF2:AF221) | AG222: =SUM(AG2:AG221)

Sheet ONBUY
A1: Date | B1: Order Number | C1: SKU | D1: IMEI | E1: Model | F1: Colour | G1: Storage | H1: Supplier | I1: BP | J1: SP | K1: SP-BP | L1: Marginal Tax | M1: Commission | N1: VAT 20% | O1: Postage | P1: P. VAT | Q1: Acc | R1: Total VAT | S1: GP | T1: GP % | U1: Total VAT NTP | V1: Postage Loss | W1: Fees Kept | X1: Repair Cost | Y1: Supplier Credit | Z1: Return Cost | AA1: Net GP £ | AB1: Return Date | AC1: Outcome | AD1: Shipping Legs | AE1: Return Reason | AF1: Comments
A2: 46227.5 | B2: ONB-5023 | C2: GOO-128GB-BLA | D2: 350100000182137 | E2: GOO-128GB-BLA | F2: BLACK | G2: 128GB | H2: CELLHUB TRADING | I2: 276.86 | J2: 347.16 | K2: =J2-I2 | L2: =K2*16.67% | M2: =J2*7% | N2: =M2*20% | O2: 0 | P2: =O2*20% | Q2: 1 | R2: =N2+P2 | S2: =K2-L2-M2-N2-O2-P2-Q2 | T2: =(S2-Z2)/I2*100 | U2: =L2-R2 | AA2: =S2-Z2
A3: 46225.5 | B3: ONB-5093 | C3: SAM-128GB-MID | D3: 350100007863567 | E3: SAM-128GB-MID | F3: Unspecified | G3: 128GB | H3: NORTHSIDE STOCK | I3: 242 | J3: 353.11 | K3: =J3-I3 | L3: =K3*16.67% | M3: =J3*7% | N3: =M3*20% | O3: 0 | P3: =O3*20% | Q3: 1 | R3: =N3+P3 | S3: =K3-L3-M3-N3-O3-P3-Q3 | T3: =(S3-Z3)/I3*100 | U3: =L3-R3 | AA3: =S3-Z3
A4: 46224.5 | B4: ONB-5068 | C4: IPH-256GB-MID | D4: 350100000538492 | E4: iPhone | F4: MIDNIGHT | G4: 256GB | H4: MOBILE WHOLESALE LTD | I4: 482.51 | J4: 628.06 | K4: =J4-I4 | L4: =K4*16.67% | M4: =J4*7% | N4: =M4*20% | O4: 0 | P4: =O4*20% | Q4: 1 | R4: =N4+P4 | S4: =K4-L4-M4-N4-O4-P4-Q4 | T4: =(S4-Z4)/I4*100 | U4: =L4-R4 | AA4: =S4-Z4
A5: 46223.5 | B5: ONB-5043 | C5: IPH-256GB-STA | D5: 350100000340517 | E5: iPhone | F5: STARLIGHT | G5: 256GB | H5: NORTHSIDE STOCK | I5: 500.85 | J5: 631.84 | K5: =J5-I5 | L5: =K5*16.67% | M5: =J5*7% | N5: =M5*20% | O5: 0 | P5: =O5*20% | Q5: 1 | R5: =N5+P5 | S5: =K5-L5-M5-N5-O5-P5-Q5 | T5: =(S5-Z5)/I5*100 | U5: =L5-R5 | AA5: =S5-Z5
A6: 46222.5 | B6: ONB-5018 | C6: IPH-128GB-BLU | D6: 350100000142542 | E6: iPhone | F6: BLUE | G6: 128GB | H6: CELLHUB TRADING | I6: 316.37 | J6: 409.99 | K6: =J6-I6 | L6: =K6*16.67% | M6: =J6*7% | N6: =M6*20% | O6: 0 | P6: =O6*20% | Q6: 1 | R6: =N6+P6 | S6: =K6-L6-M6-N6-O6-P6-Q6 | T6: =(S6-Z6)/I6*100 | U6: =L6-R6 | AA6: =S6-Z6
A7: 46220.5 | B7: ONB-5088 | C7: IPH-64GB-STA | D7: 350100000696872 | E7: iPhone | F7: STARLIGHT | G7: 64GB | H7: NORTHSIDE STOCK | I7: 186.57 | J7: 264.87 | K7: =J7-I7 | L7: =K7*16.67% | M7: =J7*7% | N7: =M7*20% | O7: 0 | P7: =O7*20% | Q7: 1 | R7: =N7+P7 | S7: =K7-L7-M7-N7-O7-P7-Q7 | T7: =(S7-Z7)/I7*100 | U7: =L7-R7 | AA7: =S7-Z7
A8: 46219.5 | B8: ONB-5063 | C8: GOO-128GB-BLU | D8: 350100000498897 | E8: GOO-128GB-BLU | F8: BLUE | G8: 128GB | H8: CELLHUB TRADING | I8: 287.02 | J8: 379.48 | K8: =J8-I8 | L8: =K8*16.67% | M8: =J8*7% | N8: =M8*20% | O8: 0 | P8: =O8*20% | Q8: 1 | R8: =N8+P8 | S8: =K8-L8-M8-N8-O8-P8-Q8 | T8: =(S8-Z8)/I8*100 | U8: =L8-R8 | AA8: =S8-Z8
A9: 46218.5 | B9: ONB-5038 | C9: SAM-256GB-MID | D9: 350100000300922 | E9: SAM-256GB-MID | F9: MIDNIGHT | G9: 256GB | H9: NORTHSIDE STOCK | I9: 422.16 | J9: 534.52 | K9: =J9-I9 | L9: =K9*16.67% | M9: =J9*7% | N9: =M9*20% | O9: 0 | P9: =O9*20% | Q9: 1 | R9: =N9+P9 | S9: =K9-L9-M9-N9-O9-P9-Q9 | T9: =(S9-Z9)/I9*100 | U9: =L9-R9 | AA9: =S9-Z9
A10: 46217.5 | B10: ONB-5013 | C10: SAM-128GB-BLU | D10: 350100000102947 | E10: SAM-128GB-BLU | F10: BLUE | G10: 128GB | H10: MOBILE WHOLESALE LTD | I10: 230.57 | J10: 310.06 | K10: =J10-I10 | L10: =K10*16.67% | M10: =J10*7% | N10: =M10*20% | O10: 0 | P10: =O10*20% | Q10: 1 | R10: =N10+P10 | S10: =K10-L10-M10-N10-O10-P10-Q10 | T10: =(S10-Z10)/I10*100 | U10: =L10-R10 | AA10: =S10-Z10
A11: 46215.5 | B11: ONB-5083 | C11: IPH-256GB-PUR | D11: 350100000657277 | E11: iPhone | F11: PURPLE | G11: 256GB | H11: MOBILE WHOLESALE LTD | I11: 511.35 | J11: 700.16 | K11: =J11-I11 | L11: =K11*16.67% | M11: =J11*7% | N11: =M11*20% | O11: 0 | P11: =O11*20% | Q11: 1 | R11: =N11+P11 | S11: =K11-L11-M11-N11-O11-P11-Q11 | T11: =(S11-Z11)/I11*100 | U11: =L11-R11 | AA11: =S11-Z11
A12: 46214.5 | B12: ONB-5058 | C12: IPH-128GB-WHI | D12: 350100000459302 | E12: iPhone | F12: WHITE | G12: 128GB | H12: PHONEBOX DIRECT | I12: 336.42 | J12: 468.11 | K12: =J12-I12 | L12: =K12*16.67% | M12: =J12*7% | N12: =M12*20% | O12: 0 | P12: =O12*20% | Q12: 1 | R12: =N12+P12 | S12: =K12-L12-M12-N12-O12-P12-Q12 | T12: =(S12-Z12)/I12*100 | U12: =L12-R12 | AA12: =S12-Z12
A13: 46213.5 | B13: ONB-5033 | C13: IPH-128GB-GRE | D13: 350100000261327 | E13: iPhone | F13: GREEN | G13: 128GB | H13: CELLHUB TRADING | I13: 209.59 | J13: 298.71 | K13: =J13-I13 | L13: =K13*16.67% | M13: =J13*7% | N13: =M13*20% | O13: 0 | P13: =O13*20% | Q13: 1 | R13: =N13+P13 | S13: =K13-L13-M13-N13-O13-P13-Q13 | T13: =(S13-Z13)/I13*100 | U13: =L13-R13 | AA13: =S13-Z13
... A21: 46204.5 | B21: ONB-5048 | C21: IPH-128GB-BLA | D21: 350100000388031 | E21: iPhone | F21: BLACK | G21: 128GB | H21: NORTHSIDE STOCK | I21: 232.81 | J21: 298.59 | K21: =J21-I21 | L21: =K21*16.67% | M21: =J21*7% | N21: =M21*20% | O21: 0 | P21: =O21*20% | Q21: 1 | R21: =N21+P21 | S21: =K21-L21-M21-N21-O21-P21-Q21 | T21: =(S21-Z21)/I21*100 | U21: =L21-R21 | AA21: =S21-Z21
K22: =IF($J22="","",J22-I22) | L22: =IF($J22="","",K22*16.67%) | M22: =IF($J22="","",J22*7%) | N22: =IF($J22="","",M22*20%) | P22: =IF($J22="","",O22*20%) | Q22: 1 | R22: =IF($J22="","",N22+P22) | S22: =IF($J22="","",K22-L22-M22-N22-O22-P22-Q22) | T22: =IF($J22="","",(S22-Z22)/I22*100) | U22: =IF($J22="","",L22-R22) | AA22: =IF($J22="","",S22-Z22)
K23: =IF($J23="","",J23-I23) | L23: =IF($J23="","",K23*16.67%) | M23: =IF($J23="","",J23*7%) | N23: =IF($J23="","",M23*20%) | P23: =IF($J23="","",O23*20%) | Q23: 1 | R23: =IF($J23="","",N23+P23) | S23: =IF($J23="","",K23-L23-M23-N23-O23-P23-Q23) | T23: =IF($J23="","",(S23-Z23)/I23*100) | U23: =IF($J23="","",L23-R23) | AA23: =IF($J23="","",S23-Z23)
K24: =IF($J24="","",J24-I24) | L24: =IF($J24="","",K24*16.67%) | M24: =IF($J24="","",J24*7%) | N24: =IF($J24="","",M24*20%) | P24: =IF($J24="","",O24*20%) | Q24: 1 | R24: =IF($J24="","",N24+P24) | S24: =IF($J24="","",K24-L24-M24-N24-O24-P24-Q24) | T24: =IF($J24="","",(S24-Z24)/I24*100) | U24: =IF($J24="","",L24-R24) | AA24: =IF($J24="","",S24-Z24)
K25: =IF($J25="","",J25-I25) | L25: =IF($J25="","",K25*16.67%) | M25: =IF($J25="","",J25*7%) | N25: =IF($J25="","",M25*20%) | P25: =IF($J25="","",O25*20%) | Q25: 1 | R25: =IF($J25="","",N25+P25) | S25: =IF($J25="","",K25-L25-M25-N25-O25-P25-Q25) | T25: =IF($J25="","",(S25-Z25)/I25*100) | U25: =IF($J25="","",L25-R25) | AA25: =IF($J25="","",S25-Z25)
K26: =IF($J26="","",J26-I26) | L26: =IF($J26="","",K26*16.67%) | M26: =IF($J26="","",J26*7%) | N26: =IF($J26="","",M26*20%) | P26: =IF($J26="","",O26*20%) | Q26: 1 | R26: =IF($J26="","",N26+P26) | S26: =IF($J26="","",K26-L26-M26-N26-O26-P26-Q26) | T26: =IF($J26="","",(S26-Z26)/I26*100) | U26: =IF($J26="","",L26-R26) | AA26: =IF($J26="","",S26-Z26)
K27: =IF($J27="","",J27-I27) | L27: =IF($J27="","",K27*16.67%) | M27: =IF($J27="","",J27*7%) | N27: =IF($J27="","",M27*20%) | P27: =IF($J27="","",O27*20%) | Q27: 1 | R27: =IF($J27="","",N27+P27) | S27: =IF($J27="","",K27-L27-M27-N27-O27-P27-Q27) | T27: =IF($J27="","",(S27-Z27)/I27*100) | U27: =IF($J27="","",L27-R27) | AA27: =IF($J27="","",S27-Z27)
K28: =IF($J28="","",J28-I28) | L28: =IF($J28="","",K28*16.67%) | M28: =IF($J28="","",J28*7%) | N28: =IF($J28="","",M28*20%) | P28: =IF($J28="","",O28*20%) | Q28: 1 | R28: =IF($J28="","",N28+P28) | S28: =IF($J28="","",K28-L28-M28-N28-O28-P28-Q28) | T28: =IF($J28="","",(S28-Z28)/I28*100) | U28: =IF($J28="","",L28-R28) | AA28: =IF($J28="","",S28-Z28)
K29: =IF($J29="","",J29-I29) | L29: =IF($J29="","",K29*16.67%) | M29: =IF($J29="","",J29*7%) | N29: =IF($J29="","",M29*20%) | P29: =IF($J29="","",O29*20%) | Q29: 1 | R29: =IF($J29="","",N29+P29) | S29: =IF($J29="","",K29-L29-M29-N29-O29-P29-Q29) | T29: =IF($J29="","",(S29-Z29)/I29*100) | U29: =IF($J29="","",L29-R29) | AA29: =IF($J29="","",S29-Z29)
K30: =IF($J30="","",J30-I30) | L30: =IF($J30="","",K30*16.67%) | M30: =IF($J30="","",J30*7%) | N30: =IF($J30="","",M30*20%) | P30: =IF($J30="","",O30*20%) | Q30: 1 | R30: =IF($J30="","",N30+P30) | S30: =IF($J30="","",K30-L30-M30-N30-O30-P30-Q30) | T30: =IF($J30="","",(S30-Z30)/I30*100) | U30: =IF($J30="","",L30-R30) | AA30: =IF($J30="","",S30-Z30)
K31: =IF($J31="","",J31-I31) | L31: =IF($J31="","",K31*16.67%) | M31: =IF($J31="","",J31*7%) | N31: =IF($J31="","",M31*20%) | P31: =IF($J31="","",O31*20%) | Q31: 1 | R31: =IF($J31="","",N31+P31) | S31: =IF($J31="","",K31-L31-M31-N31-O31-P31-Q31) | T31: =IF($J31="","",(S31-Z31)/I31*100) | U31: =IF($J31="","",L31-R31) | AA31: =IF($J31="","",S31-Z31)
K32: =IF($J32="","",J32-I32) | L32: =IF($J32="","",K32*16.67%) | M32: =IF($J32="","",J32*7%) | N32: =IF($J32="","",M32*20%) | P32: =IF($J32="","",O32*20%) | Q32: 1 | R32: =IF($J32="","",N32+P32) | S32: =IF($J32="","",K32-L32-M32-N32-O32-P32-Q32) | T32: =IF($J32="","",(S32-Z32)/I32*100) | U32: =IF($J32="","",L32-R32) | AA32: =IF($J32="","",S32-Z32)
K33: =IF($J33="","",J33-I33) | L33: =IF($J33="","",K33*16.67%) | M33: =IF($J33="","",J33*7%) | N33: =IF($J33="","",M33*20%) | P33: =IF($J33="","",O33*20%) | Q33: 1 | R33: =IF($J33="","",N33+P33) | S33: =IF($J33="","",K33-L33-M33-N33-O33-P33-Q33) | T33: =IF($J33="","",(S33-Z33)/I33*100) | U33: =IF($J33="","",L33-R33) | AA33: =IF($J33="","",S33-Z33)
... K221: =IF($J221="","",J221-I221) | L221: =IF($J221="","",K221*16.67%) | M221: =IF($J221="","",J221*7%) | N221: =IF($J221="","",M221*20%) | P221: =IF($J221="","",O221*20%) | Q221: 1 | R221: =IF($J221="","",N221+P221) | S221: =IF($J221="","",K221-L221-M221-N221-O221-P221-Q221) | T221: =IF($J221="","",(S221-Z221)/I221*100) | U221: =IF($J221="","",L221-R221) | AA221: =IF($J221="","",S221-Z221)
A222: TOTAL | I222: =SUM(I2:I221) | J222: =SUM(J2:J221) | K222: =SUM(K2:K221) | L222: =SUM(L2:L221) | M222: =SUM(M2:M221) | N222: =SUM(N2:N221) | O222: =SUM(O2:O221) | P222: =SUM(P2:P221) | ... S222: =SUM(S2:S221) | T222: =IFERROR((S222-Z222)/I222*100,0) | U222: =SUM(U2:U221) | V222: =SUM(V2:V221) | W222: =SUM(W2:W221) | X222: =SUM(X2:X221) | Y222: =SUM(Y2:Y221) | Z222: =SUM(Z2:Z221) | AA222: =SUM(AA2:AA221)

Sheet TEMU
A1: Date | B1: Order Number | C1: SKU | D1: IMEI | E1: Model | F1: Colour | G1: Storage | H1: Supplier | I1: Quantity | J1: BP | K1: SP | L1: SP-BP | M1: Marginal Tax | N1: Commission | O1: Commission VAT | P1: Commission+VAT | Q1: Postage | R1: P. VAT | S1: Acc | T1: Total VAT | U1: GP | V1: GP % | W1: Total VAT NTP | X1: Postage Loss | Y1: Fees Kept | Z1: Repair Cost | AA1: Supplier Credit | AB1: Return Cost | AC1: Net GP £ | AD1: Return Date | AE1: Outcome | AF1: Shipping Legs | AG1: Return Reason | AH1: Comments
A2: 46226.5 | B2: TEM-5094 | C2: SAM-256GB-PUR | D2: 350100007871486 | E2: SAM-256GB-PUR | F2: Unspecified | G2: 256GB | H2: MOBILE WHOLESALE LTD | I2: 1 | J2: 417.16 | K2: 566.56 | L2: =K2-J2 | M2: =L2*16.67% | N2: =K2*4.61% | O2: =N2*20% | P2: =N2+O2 | Q2: 6.3 | R2: =Q2*20% | S2: 1 | T2: =R2 | U2: =L2-M2-N2-Q2-R2-S2 | V2: =(U2-AB2)/J2*100 | W2: =M2-T2 | AC2: =U2-AB2
A3: 46225.5 | B3: TEM-5069 | C3: SAM-128GB-BLU | D3: 350100000546411 | E3: SAM-128GB-BLU | F3: BLUE | G3: 128GB | H3: MOBILE WHOLESALE LTD | I3: 1 | J3: 263.11 | K3: 334.65 | L3: =K3-J3 | M3: =L3*16.67% | N3: =K3*4.61% | O3: =N3*20% | P3: =N3+O3 | Q3: 2 | R3: =Q3*20% | S3: 1 | T3: =R3 | U3: =L3-M3-N3-Q3-R3-S3 | V3: =(U3-AB3)/J3*100 | W3: =M3-T3 | AC3: =U3-AB3
A4: 46224.5 | B4: TEM-5044 | C4: IPH-256GB-MID | D4: 350100000348436 | E4: iPhone | F4: MIDNIGHT | G4: 256GB | H4: MOBILE WHOLESALE LTD | I4: 1 | J4: 484.06 | K4: 721.16 | L4: =K4-J4 | M4: =L4*16.67% | N4: =K4*4.61% | O4: =N4*20% | P4: =N4+O4 | Q4: 2 | R4: =Q4*20% | S4: 1 | T4: =R4 | U4: =L4-M4-N4-Q4-R4-S4 | V4: =(U4-AB4)/J4*100 | W4: =M4-T4 | AC4: =U4-AB4
A5: 46223.5 | B5: TEM-5019 | C5: IPH-256GB-GRA | D5: 350100000150461 | E5: iPhone | F5: GRAPHITE | G5: 256GB | H5: CELLHUB TRADING | I5: 1 | J5: 529.23 | K5: 740.45 | L5: =K5-J5 | M5: =L5*16.67% | N5: =K5*4.61% | O5: =N5*20% | P5: =N5+O5 | Q5: 8 | R5: =Q5*20% | S5: 1 | T5: =R5 | U5: =L5-M5-N5-Q5-R5-S5 | V5: =(U5-AB5)/J5*100 | W5: =M5-T5 | AC5: =U5-AB5
A6: 46221.5 | B6: TEM-5089 | C6: IPH-128GB-MID | D6: 350100000704791 | E6: iPhone | F6: MIDNIGHT | G6: 128GB | H6: MOBILE WHOLESALE LTD | I6: 1 | J6: 227.85 | K6: 304.26 | L6: =K6-J6 | M6: =L6*16.67% | N6: =K6*4.61% | O6: =N6*20% | P6: =N6+O6 | Q6: 8 | R6: =Q6*20% | S6: 1 | T6: =R6 | U6: =L6-M6-N6-Q6-R6-S6 | V6: =(U6-AB6)/J6*100 | W6: =M6-T6 | AC6: =U6-AB6
A7: 46220.5 | B7: TEM-5064 | C7: IPH-64GB-GRE | D7: 350100000506816 | E7: iPhone | F7: GREEN | G7: 64GB | H7: MOBILE WHOLESALE LTD | I7: 1 | J7: 197.28 | K7: 253.57 | L7: =K7-J7 | M7: =L7*16.67% | N7: =K7*4.61% | O7: =N7*20% | P7: =N7+O7 | Q7: 8 | R7: =Q7*20% | S7: 1 | T7: =R7 | U7: =L7-M7-N7-Q7-R7-S7 | V7: =(U7-AB7)/J7*100 | W7: =M7-T7 | AC7: =U7-AB7
A8: 46219.5 | B8: TEM-5039 | C8: GOO-128GB-GRA | D8: 350100000308841 | E8: GOO-128GB-GRA | F8: GRAPHITE | G8: 128GB | H8: MOBILE WHOLESALE LTD | I8: 1 | J8: 268.59 | K8: 354.91 | L8: =K8-J8 | M8: =L8*16.67% | N8: =K8*4.61% | O8: =N8*20% | P8: =N8+O8 | Q8: 8 | R8: =Q8*20% | S8: 1 | T8: =R8 | U8: =L8-M8-N8-Q8-R8-S8 | V8: =(U8-AB8)/J8*100 | W8: =M8-T8 | AC8: =U8-AB8
A9: 46218.5 | B9: TEM-5014 | C9: SAM-256GB-WHI | D9: 350100000110866 | E9: SAM-256GB-WHI | F9: WHITE | G9: 256GB | H9: PHONEBOX DIRECT | I9: 1 | J9: 450.57 | K9: 603.85 | L9: =K9-J9 | M9: =L9*16.67% | N9: =K9*4.61% | O9: =N9*20% | P9: =N9+O9 | Q9: 2 | R9: =Q9*20% | S9: 1 | T9: =R9 | U9: =L9-M9-N9-Q9-R9-S9 | V9: =(U9-AB9)/J9*100 | W9: =M9-T9 | AC9: =U9-AB9
A10: 46216.5 | B10: TEM-5084 | C10: SAM-128GB-GRA | D10: 350100000673115 | E10: SAM-128GB-GRA | F10: GRAPHITE | G10: 128GB | H10: NORTHSIDE STOCK | I10: 1 | J10: 246.21 | K10: 344.78 | L10: =K10-J10 | M10: =L10*16.67% | N10: =K10*4.61% | O10: =N10*20% | P10: =N10+O10 | Q10: 6.3 | R10: =Q10*20% | S10: 1 | T10: =R10 | U10: =L10-M10-N10-Q10-R10-S10 | V10: =(U10-AB10)/J10*100 | W10: =M10-T10 | AC10: =U10-AB10
A11: 46215.5 | B11: TEM-5059 | C11: IPH-256GB-BLA | D11: 350100000467221 | E11: iPhone | F11: BLACK | G11: 256GB | H11: PHONEBOX DIRECT | I11: 1 | J11: 507.95 | K11: 670.51 | L11: =K11-J11 | M11: =L11*16.67% | N11: =K11*4.61% | O11: =N11*20% | P11: =N11+O11 | Q11: 8 | R11: =Q11*20% | S11: 1 | T11: =R11 | U11: =L11-M11-N11-Q11-R11-S11 | V11: =(U11-AB11)/J11*100 | W11: =M11-T11 | AC11: =U11-AB11
A12: 46214.5 | B12: TEM-5034 | C12: IPH-128GB-GRE | D12: 350100000269246 | E12: iPhone | F12: GREEN | G12: 128GB | H12: CELLHUB TRADING | I12: 1 | J12: 305.4 | K12: 390.8 | L12: =K12-J12 | M12: =L12*16.67% | N12: =K12*4.61% | O12: =N12*20% | P12: =N12+O12 | Q12: 8 | R12: =Q12*20% | S12: 1 | T12: =R12 | U12: =L12-M12-N12-Q12-R12-S12 | V12: =(U12-AB12)/J12*100 | W12: =M12-T12 | AC12: =U12-AB12
A13: 46213.5 | B13: TEM-5009 | C13: IPH-128GB-WHI | D13: 350100000071271 | E13: iPhone | F13: WHITE | G13: 128GB | H13: CELLHUB TRADING | I13: 1 | J13: 229.85 | K13: 322.37 | L13: =K13-J13 | M13: =L13*16.67% | N13: =K13*4.61% | O13: =N13*20% | P13: =N13+O13 | Q13: 8 | R13: =Q13*20% | S13: 1 | T13: =R13 | U13: =L13-M13-N13-Q13-R13-S13 | V13: =(U13-AB13)/J13*100 | W13: =M13-T13 | AC13: =U13-AB13
... A21: 46204.5 | B21: TEM-5024 | C21: IPH-128GB-STA | D21: 350100000197975 | E21: iPhone | F21: STARLIGHT | G21: 128GB | H21: PHONEBOX DIRECT | I21: 1 | J21: 233.36 | K21: 306.12 | L21: =K21-J21 | M21: =L21*16.67% | N21: =K21*4.61% | O21: =N21*20% | P21: =N21+O21 | Q21: 8 | R21: =Q21*20% | S21: 1 | T21: =R21 | U21: =L21-M21-N21-Q21-R21-S21 | V21: =(U21-AB21)/J21*100 | W21: =M21-T21 | AC21: =U21-AB21
L22: =IF($K22="","",K22-J22) | M22: =IF($K22="","",L22*16.67%) | N22: =IF($K22="","",K22*3.96%) | O22: =IF($K22="","",N22*20%) | P22: =IF($K22="","",N22+O22) | R22: =IF($K22="","",Q22*20%) | S22: 1 | T22: =IF($K22="","",R22) | U22: =IF($K22="","",L22-M22-N22-Q22-R22-S22) | V22: =IF($K22="","",(U22-AB22)/J22*100) | W22: =IF($K22="","",M22-T22) | AC22: =IF($K22="","",U22-AB22)
L23: =IF($K23="","",K23-J23) | M23: =IF($K23="","",L23*16.67%) | N23: =IF($K23="","",K23*3.96%) | O23: =IF($K23="","",N23*20%) | P23: =IF($K23="","",N23+O23) | R23: =IF($K23="","",Q23*20%) | S23: 1 | T23: =IF($K23="","",R23) | U23: =IF($K23="","",L23-M23-N23-Q23-R23-S23) | V23: =IF($K23="","",(U23-AB23)/J23*100) | W23: =IF($K23="","",M23-T23) | AC23: =IF($K23="","",U23-AB23)
L24: =IF($K24="","",K24-J24) | M24: =IF($K24="","",L24*16.67%) | N24: =IF($K24="","",K24*3.96%) | O24: =IF($K24="","",N24*20%) | P24: =IF($K24="","",N24+O24) | R24: =IF($K24="","",Q24*20%) | S24: 1 | T24: =IF($K24="","",R24) | U24: =IF($K24="","",L24-M24-N24-Q24-R24-S24) | V24: =IF($K24="","",(U24-AB24)/J24*100) | W24: =IF($K24="","",M24-T24) | AC24: =IF($K24="","",U24-AB24)
L25: =IF($K25="","",K25-J25) | M25: =IF($K25="","",L25*16.67%) | N25: =IF($K25="","",K25*3.96%) | O25: =IF($K25="","",N25*20%) | P25: =IF($K25="","",N25+O25) | R25: =IF($K25="","",Q25*20%) | S25: 1 | T25: =IF($K25="","",R25) | U25: =IF($K25="","",L25-M25-N25-Q25-R25-S25) | V25: =IF($K25="","",(U25-AB25)/J25*100) | W25: =IF($K25="","",M25-T25) | AC25: =IF($K25="","",U25-AB25)
L26: =IF($K26="","",K26-J26) | M26: =IF($K26="","",L26*16.67%) | N26: =IF($K26="","",K26*3.96%) | O26: =IF($K26="","",N26*20%) | P26: =IF($K26="","",N26+O26) | R26: =IF($K26="","",Q26*20%) | S26: 1 | T26: =IF($K26="","",R26) | U26: =IF($K26="","",L26-M26-N26-Q26-R26-S26) | V26: =IF($K26="","",(U26-AB26)/J26*100) | W26: =IF($K26="","",M26-T26) | AC26: =IF($K26="","",U26-AB26)
L27: =IF($K27="","",K27-J27) | M27: =IF($K27="","",L27*16.67%) | N27: =IF($K27="","",K27*3.96%) | O27: =IF($K27="","",N27*20%) | P27: =IF($K27="","",N27+O27) | R27: =IF($K27="","",Q27*20%) | S27: 1 | T27: =IF($K27="","",R27) | U27: =IF($K27="","",L27-M27-N27-Q27-R27-S27) | V27: =IF($K27="","",(U27-AB27)/J27*100) | W27: =IF($K27="","",M27-T27) | AC27: =IF($K27="","",U27-AB27)
L28: =IF($K28="","",K28-J28) | M28: =IF($K28="","",L28*16.67%) | N28: =IF($K28="","",K28*3.96%) | O28: =IF($K28="","",N28*20%) | P28: =IF($K28="","",N28+O28) | R28: =IF($K28="","",Q28*20%) | S28: 1 | T28: =IF($K28="","",R28) | U28: =IF($K28="","",L28-M28-N28-Q28-R28-S28) | V28: =IF($K28="","",(U28-AB28)/J28*100) | W28: =IF($K28="","",M28-T28) | AC28: =IF($K28="","",U28-AB28)
L29: =IF($K29="","",K29-J29) | M29: =IF($K29="","",L29*16.67%) | N29: =IF($K29="","",K29*3.96%) | O29: =IF($K29="","",N29*20%) | P29: =IF($K29="","",N29+O29) | R29: =IF($K29="","",Q29*20%) | S29: 1 | T29: =IF($K29="","",R29) | U29: =IF($K29="","",L29-M29-N29-Q29-R29-S29) | V29: =IF($K29="","",(U29-AB29)/J29*100) | W29: =IF($K29="","",M29-T29) | AC29: =IF($K29="","",U29-AB29)
L30: =IF($K30="","",K30-J30) | M30: =IF($K30="","",L30*16.67%) | N30: =IF($K30="","",K30*3.96%) | O30: =IF($K30="","",N30*20%) | P30: =IF($K30="","",N30+O30) | R30: =IF($K30="","",Q30*20%) | S30: 1 | T30: =IF($K30="","",R30) | U30: =IF($K30="","",L30-M30-N30-Q30-R30-S30) | V30: =IF($K30="","",(U30-AB30)/J30*100) | W30: =IF($K30="","",M30-T30) | AC30: =IF($K30="","",U30-AB30)
L31: =IF($K31="","",K31-J31) | M31: =IF($K31="","",L31*16.67%) | N31: =IF($K31="","",K31*3.96%) | O31: =IF($K31="","",N31*20%) | P31: =IF($K31="","",N31+O31) | R31: =IF($K31="","",Q31*20%) | S31: 1 | T31: =IF($K31="","",R31) | U31: =IF($K31="","",L31-M31-N31-Q31-R31-S31) | V31: =IF($K31="","",(U31-AB31)/J31*100) | W31: =IF($K31="","",M31-T31) | AC31: =IF($K31="","",U31-AB31)
L32: =IF($K32="","",K32-J32) | M32: =IF($K32="","",L32*16.67%) | N32: =IF($K32="","",K32*3.96%) | O32: =IF($K32="","",N32*20%) | P32: =IF($K32="","",N32+O32) | R32: =IF($K32="","",Q32*20%) | S32: 1 | T32: =IF($K32="","",R32) | U32: =IF($K32="","",L32-M32-N32-Q32-R32-S32) | V32: =IF($K32="","",(U32-AB32)/J32*100) | W32: =IF($K32="","",M32-T32) | AC32: =IF($K32="","",U32-AB32)
L33: =IF($K33="","",K33-J33) | M33: =IF($K33="","",L33*16.67%) | N33: =IF($K33="","",K33*3.96%) | O33: =IF($K33="","",N33*20%) | P33: =IF($K33="","",N33+O33) | R33: =IF($K33="","",Q33*20%) | S33: 1 | T33: =IF($K33="","",R33) | U33: =IF($K33="","",L33-M33-N33-Q33-R33-S33) | V33: =IF($K33="","",(U33-AB33)/J33*100) | W33: =IF($K33="","",M33-T33) | AC33: =IF($K33="","",U33-AB33)
... L221: =IF($K221="","",K221-J221) | M221: =IF($K221="","",L221*16.67%) | N221: =IF($K221="","",K221*3.96%) | O221: =IF($K221="","",N221*20%) | P221: =IF($K221="","",N221+O221) | R221: =IF($K221="","",Q221*20%) | S221: 1 | T221: =IF($K221="","",R221) | U221: =IF($K221="","",L221-M221-N221-Q221-R221-S221) | V221: =IF($K221="","",(U221-AB221)/J221*100) | W221: =IF($K221="","",M221-T221) | AC221: =IF($K221="","",U221-AB221)
A222: TOTAL | I222: =SUM(I2:I221) | J222: =SUM(J2:J221) | K222: =SUM(K2:K221) | L222: =SUM(L2:L221) | M222: =SUM(M2:M221) | N222: =SUM(N2:N221) | O222: =SUM(O2:O221) | P222: =SUM(P2:P221) | ... U222: =SUM(U2:U221) | V222: =IFERROR((U222-AB222)/J222*100,0) | W222: =SUM(W2:W221) | X222: =SUM(X2:X221) | Y222: =SUM(Y2:Y221) | Z222: =SUM(Z2:Z221) | AA222: =SUM(AA2:AA221) | AB222: =SUM(AB2:AB221) | AC222: =SUM(AC2:AC221)

Sheet Returns & Profit
A1: RETURNS & PROFIT BY MARKETPLACE
